Workbook

Sheet CPI
A1: Thailand | B1: Philippines | C1: Korea | D1: Indonesia | E1: Date
A2: 110.05441 | B2: 115.1958 | C2: 109.57517 | D2: 130.42047 | E2: 2015-M01 | W2: Thailand | X2: Philippines | Y2: Korea | Z2: Indonesia
A3: 110.18936 | B3: 115.30367 | C3: 109.51034 | D3: 129.94805 | E3: 2015-M02 | V3: Min | W3: =MIN(A2:A130) -> 108.11463 | X3: =MIN(B2:B130) -> 115.1958 | Y3: =MIN(C2:C130) -> 109.51034 | Z3: =MIN(D2:D130) -> 129.94805
A4: 110.37621 | B4: 115.1958 | C4: 109.52076 | D4: 130.16778 | E4: 2015-M03 | V4: Max | W4: =MAX(A2:A130) -> 124.87834 | X4: =MAX(B2:B130) -> 162.70014 | Y4: =MAX(C2:C130) -> 135.52899 | Z4: =MAX(D2:D130) -> 177.0438
A5: 110.39697 | B5: 115.41153 | C5: 109.55433 | D5: 130.6402 | E5: 2015-M04 | V5: Mean | W5: =AVERAGE(A2:A130) -> 114.20457 | X5: =AVERAGE(B2:B130) -> 135.91966 | Y5: =AVERAGE(C2:C130) -> 119.55551 | Z5: =AVERAGE(D2:D130) -> 154.0746
A6: 110.58382 | B6: 115.30367 | C6: 109.86114 | D6: 131.28841 | E6: 2015-M05 | V6: Std dev | W6: =_xlfn.STDEV.S(A2:A130) -> 4.5192755 | X6: =_xlfn.STDEV.S(B2:B130) -> 15.960772 | Y6: =_xlfn.STDEV.S(C2:C130) -> 8.2614305 | Z6: =_xlfn.STDEV.S(D2:D130) -> 13.659286
A7: 110.698 | B7: 115.30367 | C7: 109.88314 | D7: 131.99154 | E7: 2015-M06 | V7: CV | W7: =W6/W5 -> 0.039571755 | X7: =X6/X5 -> 0.11742798 | Y7: =Y6/Y5 -> 0.069101213 | Z7: =Z6/Z5 -> 0.088653715
A8: 110.62534 | B8: 115.51939 | C8: 110.08112 | D8: 133.22202 | E8: 2015-M07 | U8: Lag 12 correlation | V8: Seasonality test | W8: =CORREL(A2:A112,A14:A124) -> 0.6972572 | X8: =CORREL(B2:B118,B14:B130) -> 0.98583306 | Y8: =CORREL(C2:C118,C14:C130) -> 0.97869279 | Z8: =CORREL(D2:D118,D14:D130) -> 0.99072401
A9: 110.37621 | B9: 115.51939 | C9: 110.23511 | D9: 133.73839 | E9: 2015-M08
A10: 110.32431 | B10: 115.30367 | C10: 109.94914 | D10: 133.67247 | E10: 2015-M09
A11: 110.5423 | B11: 115.41153 | C11: 109.94914 | D11: 133.5626 | E11: 2015-M10
A12: 110.18936 | B12: 115.73511 | C12: 109.74074 | D12: 133.83727 | E12: 2015-M11
A13: 109.76376 | B13: 115.95083 | C13: 110.06954 | D13: 135.12268 | E13: 2015-M12
A14: 109.4731 | B14: 116.05869 | C14: 110.2571 | D14: 135.81484 | E14: 2016-M01
A15: 109.63919 | B15: 115.84297 | C15: 110.72947 | D15: 135.69398 | E15: 2016-M02
A16: 109.86756 | B16: 115.84297 | C16: 110.4435 | D16: 135.95766 | E16: 2016-M03
A17: 110.46963 | B17: 116.16656 | C17: 110.6519 | D17: 135.34241 | E17: 2016-M04
A18: 111.09246 | B18: 116.38228 | C18: 110.7179 | D18: 135.66103 | E18: 2016-M05
A19: 111.12361 | B19: 116.81372 | C19: 110.6959 | D19: 136.55093 | E19: 2016-M06
A20: 110.73953 | B20: 117.02945 | C20: 110.4875 | D20: 137.49576 | E20: 2016-M07
... A23: 110.916 | B23: 117.46089 | C23: 111.58507 | D23: 137.97917 | E23: 2016-M10
A24: 110.85371 | B24: 118.10806 | C24: 111.42067 | D24: 138.62736 | E24: 2016-M11 | H24: The aggregated CPI plot shows that consumer price levels rise steadily across all four countries between 2015 and 2025. Indonesia consistently records the highest CPI level throughout the sample, followed by the Philippines, while Thailand and Korea maintain lower and more stable price levels. Despite these differences in relative level, all four countries display a similar upward trajectory, reflecting broad regional inflationary pressure. The temporary dip visible in Thailand’s CPI around 2020 aligns with the COVID-19 shock, after which all countries resume a gradually rising path. Overall, the CPI series indicate persistent and synchronized inflation trends, which supports the relevance of a comparative analysis of inflation dynamics across these economies.
A25: 110.99904 | B25: 118.5395 | C25: 111.54223 | D25: 139.20965 | E25: 2016-M12
A26: 111.17187 | B26: 118.97095 | C26: 112.72779 | D26: 140.56099 | E26: 2017-M01
A27: 111.216 | B27: 119.40239 | C27: 113.03576 | D27: 140.89059 | E27: 2017-M02
A28: 110.70842 | B28: 119.40239 | C28: 112.95819 | D28: 140.86861 | E28: 2017-M03
A29: 110.88497 | B29: 119.83384 | C29: 112.81578 | D29: 140.98947 | E29: 2017-M04
A30: 111.05049 | B30: 119.72598 | C30: 112.93619 | D30: 141.53879 | E30: 2017-M05
A31: 111.07256 | B31: 119.72598 | C31: 112.69537 | D31: 142.51658 | E31: 2017-M06
A32: 110.92911 | B32: 119.83384 | C32: 112.88178 | D32: 142.8242 | E32: 2017-M07
A33: 111.05049 | B33: 120.04956 | C33: 113.52897 | D33: 142.72532 | E33: 2017-M08
A34: 111.69049 | B34: 120.80459 | C34: 113.66096 | D34: 142.9121 | E34: 2017-M09
A35: 111.86704 | B35: 121.12817 | C35: 113.55097 | D35: 142.92308 | E35: 2017-M10
A36: 111.94428 | B36: 121.66748 | C36: 112.70579 | D36: 143.20873 | E36: 2017-M11
... A124: 121.7662 | B124: 161.81383 | C124: 134.6375 | D124: 174.56903 | E124: 2025-M03
B125: 161.18076 | C125: 134.7417 | D125: 176.6042 | E125: 2025-M04
B126: 161.05414 | C126: 134.61435 | D126: 175.95295 | E126: 2025-M05
B127: 161.18076 | C127: 134.66066 | D127: 176.27858 | E127: 2025-M06
B128: 161.68722 | C128: 134.90379 | D128: 176.81586 | E128: 2025-M07
B129: 162.70014 | C129: 134.82274 | D129: 176.66933 | E129: 2025-M08
...

Sheet CPI base year 2015-01
A1: Date | B1: Thailand | C1: Philippines | D1: Korea | E1: Indonesia
A2: 2015-M01 | B2: =CPI!A2/CPI!$A$2*100 -> 100 | C2: =CPI!B2/CPI!$B$2*100 -> 100 | D2: =CPI!C2/CPI!$C$2*100 -> 100 | E2: =CPI!D2/CPI!$D$2*100 -> 100 | W2: Thailand | X2: Philippines | Y2: Korea | Z2: Indonesia
A3: 2015-M02 | B3: =CPI!A3/CPI!$A$2*100 -> 100.12262 | C3: =CPI!B3/CPI!$B$2*100 -> 100.09363 | D3: =CPI!C3/CPI!$C$2*100 -> 99.94083 | E3: =CPI!D3/CPI!$D$2*100 -> 99.637771 | V3: Min | W3: =MIN(B2:B130) -> 98.237434 | X3: =MIN(C2:C130) -> 100 | Y3: =MIN(D2:D130) -> 99.94083 | Z3: =MIN(E2:E130) -> 99.637771
A4: 2015-M03 | B4: =CPI!A4/CPI!$A$2*100 -> 100.2924 | C4: =CPI!B4/CPI!$B$2*100 -> 100 | D4: =CPI!C4/CPI!$C$2*100 -> 99.95034 | E4: =CPI!D4/CPI!$D$2*100 -> 99.806252 | V4: Max | W4: =MAX(B2:B130) -> 113.46964 | X4: =MAX(C2:C130) -> 141.2379 | Y4: =MAX(D2:D130) -> 123.68585 | Z4: =MAX(E2:E130) -> 135.74848
A5: 2015-M04 | B5: =CPI!A5/CPI!$A$2*100 -> 100.31126 | C5: =CPI!B5/CPI!$B$2*100 -> 100.18727 | D5: =CPI!C5/CPI!$C$2*100 -> 99.980981 | E5: =CPI!D5/CPI!$D$2*100 -> 100.16848 | V5: Mean | W5: =AVERAGE(B2:B130) -> 103.77101 | X5: =AVERAGE(C2:C130) -> 117.99012 | Y5: =AVERAGE(D2:D130) -> 109.10821 | Z5: =AVERAGE(E2:E130) -> 118.13682
A6: 2015-M05 | B6: =CPI!A6/CPI!$A$2*100 -> 100.48104 | C6: =CPI!B6/CPI!$B$2*100 -> 100.09363 | D6: =CPI!C6/CPI!$C$2*100 -> 100.26098 | E6: =CPI!D6/CPI!$D$2*100 -> 100.6655 | V6: Std dev | W6: =_xlfn.STDEV.S(B2:B130) -> 4.106401 | X6: =_xlfn.STDEV.S(C2:C130) -> 13.855341 | Y6: =_xlfn.STDEV.S(D2:D130) -> 7.5395094 | Z6: =_xlfn.STDEV.S(E2:E130) -> 10.473268
A7: 2015-M06 | B7: =CPI!A7/CPI!$A$2*100 -> 100.5848 | C7: =CPI!B7/CPI!$B$2*100 -> 100.09363 | D7: =CPI!C7/CPI!$C$2*100 -> 100.28106 | E7: =CPI!D7/CPI!$D$2*100 -> 101.20462 | V7: CV | W7: =W6/W5 -> 0.039571755 | X7: =X6/X5 -> 0.11742798 | Y7: =Y6/Y5 -> 0.069101213 | Z7: =Z6/Z5 -> 0.088653715
A8: 2015-M07 | B8: =CPI!A8/CPI!$A$2*100 -> 100.51877 | C8: =CPI!B8/CPI!$B$2*100 -> 100.2809 | D8: =CPI!C8/CPI!$C$2*100 -> 100.46174 | E8: =CPI!D8/CPI!$D$2*100 -> 102.14809
A9: 2015-M08 | B9: =CPI!A9/CPI!$A$2*100 -> 100.2924 | C9: =CPI!B9/CPI!$B$2*100 -> 100.2809 | D9: =CPI!C9/CPI!$C$2*100 -> 100.60226 | E9: =CPI!D9/CPI!$D$2*100 -> 102.54402
A10: 2015-M09 | B10: =CPI!A10/CPI!$A$2*100 -> 100.24524 | C10: =CPI!B10/CPI!$B$2*100 -> 100.09363 | D10: =CPI!C10/CPI!$C$2*100 -> 100.34128 | E10: =CPI!D10/CPI!$D$2*100 -> 102.49347
A11: 2015-M10 | B11: =CPI!A11/CPI!$A$2*100 -> 100.44331 | C11: =CPI!B11/CPI!$B$2*100 -> 100.18727 | D11: =CPI!C11/CPI!$C$2*100 -> 100.34128 | E11: =CPI!D11/CPI!$D$2*100 -> 102.40923
A12: 2015-M11 | B12: =CPI!A12/CPI!$A$2*100 -> 100.12262 | C12: =CPI!B12/CPI!$B$2*100 -> 100.46816 | D12: =CPI!C12/CPI!$C$2*100 -> 100.15109 | E12: =CPI!D12/CPI!$D$2*100 -> 102.61983
A13: 2015-M12 | B13: =CPI!A13/CPI!$A$2*100 -> 99.735899 | C13: =CPI!B13/CPI!$B$2*100 -> 100.65543 | D13: =CPI!C13/CPI!$C$2*100 -> 100.45117 | E13: =CPI!D13/CPI!$D$2*100 -> 103.60542
A14: 2016-M01 | B14: =CPI!A14/CPI!$A$2*100 -> 99.471798 | C14: =CPI!B14/CPI!$B$2*100 -> 100.74906 | D14: =CPI!C14/CPI!$C$2*100 -> 100.62234 | E14: =CPI!D14/CPI!$D$2*100 -> 104.13613
A15: 2016-M02 | B15: =CPI!A15/CPI!$A$2*100 -> 99.622713 | C15: =CPI!B15/CPI!$B$2*100 -> 100.5618 | D15: =CPI!C15/CPI!$C$2*100 -> 101.05343 | E15: =CPI!D15/CPI!$D$2*100 -> 104.04347
A16: 2016-M03 | B16: =CPI!A16/CPI!$A$2*100 -> 99.830221 | C16: =CPI!B16/CPI!$B$2*100 -> 100.5618 | D16: =CPI!C16/CPI!$C$2*100 -> 100.79245 | E16: =CPI!D16/CPI!$D$2*100 -> 104.24564
A17: 2016-M04 | B17: =CPI!A17/CPI!$A$2*100 -> 100.37729 | C17: =CPI!B17/CPI!$B$2*100 -> 100.8427 | D17: =CPI!C17/CPI!$C$2*100 -> 100.98264 | E17: =CPI!D17/CPI!$D$2*100 -> 103.77391
A18: 2016-M05 | B18: =CPI!A18/CPI!$A$2*100 -> 100.94322 | C18: =CPI!B18/CPI!$B$2*100 -> 101.02996 | D18: =CPI!C18/CPI!$C$2*100 -> 101.04287 | E18: =CPI!D18/CPI!$D$2*100 -> 104.0182
A19: 2016-M06 | B19: =CPI!A19/CPI!$A$2*100 -> 100.97151 | C19: =CPI!B19/CPI!$B$2*100 -> 101.40449 | D19: =CPI!C19/CPI!$C$2*100 -> 101.02279 | E19: =CPI!D19/CPI!$D$2*100 -> 104.70054
... A124: 2025-M03 | B124: =CPI!A124/CPI!$A$2*100 -> 110.64182 | C124: =CPI!B124/CPI!$B$2*100 -> 140.46851 | D124: =CPI!C124/CPI!$C$2*100 -> 122.87227 | E124: =CPI!D124/CPI!$D$2*100 -> 133.85094
A125: 2025-M04 | C125: =CPI!B125/CPI!$B$2*100 -> 139.91895 | D125: =CPI!C125/CPI!$C$2*100 -> 122.96736 | E125: =CPI!D125/CPI!$D$2*100 -> 135.41141
A126: 2025-M05 | C126: =CPI!B126/CPI!$B$2*100 -> 139.80904 | D126: =CPI!C126/CPI!$C$2*100 -> 122.85114 | E126: =CPI!D126/CPI!$D$2*100 -> 134.91206
A127: 2025-M06 | C127: =CPI!B127/CPI!$B$2*100 -> 139.91895 | D127: =CPI!C127/CPI!$C$2*100 -> 122.8934 | E127: =CPI!D127/CPI!$D$2*100 -> 135.16174
A128: 2025-M07 | C128: =CPI!B128/CPI!$B$2*100 -> 140.3586 | D128: =CPI!C128/CPI!$C$2*100 -> 123.11529 | E128: =CPI!D128/CPI!$D$2*100 -> 135.5737
A129: 2025-M08 | C129: =CPI!B129/CPI!$B$2*100 -> 141.2379 | D129: =CPI!C129/CPI!$C$2*100 -> 123.04132 | E129: =CPI!D129/CPI!$D$2*100 -> 135.46135
A130: 2025-M09 | C130: =CPI!B130/CPI!$B$2*100 -> 141.2379 | D130: =CPI!C130/CPI!$C$2*100 -> 123.68585 | E130: =CPI!D130/CPI!$D$2*100 -> 135.74848

Sheet Log(CPI)
A2: Date | B2: Thailand | C2: Philippines | D2: Korea | E2: Indonesia
A3: 2015-M01 | B3: =LOG('CPI base year 2015-01'!B2) -> 2 | C3: =LOG('CPI base year 2015-01'!C2) -> 2 | D3: =LOG('CPI base year 2015-01'!D2) -> 2 | E3: =LOG('CPI base year 2015-01'!E2) -> 2
A4: 2015-M02 | B4: =LOG('CPI base year 2015-01'!B3) -> 2.0005322 | C4: =LOG('CPI base year 2015-01'!C3) -> 2.0004065 | D4: =LOG('CPI base year 2015-01'!D3) -> 1.999743 | E4: =LOG('CPI base year 2015-01'!E3) -> 1.998424
A5: 2015-M03 | B5: =LOG('CPI base year 2015-01'!B4) -> 2.001268 | C5: =LOG('CPI base year 2015-01'!C4) -> 2 | D5: =LOG('CPI base year 2015-01'!D4) -> 1.9997843 | E5: =LOG('CPI base year 2015-01'!E4) -> 1.9991577
A6: 2015-M04 | B6: =LOG('CPI base year 2015-01'!B5) -> 2.0013497 | C6: =LOG('CPI base year 2015-01'!C5) -> 2.0008125 | D6: =LOG('CPI base year 2015-01'!D5) -> 1.9999174 | E6: =LOG('CPI base year 2015-01'!E5) -> 2.0007311
A7: 2015-M05 | B7: =LOG('CPI base year 2015-01'!B6) -> 2.0020841 | C7: =LOG('CPI base year 2015-01'!C6) -> 2.0004065 | D7: =LOG('CPI base year 2015-01'!D6) -> 2.0011319 | E7: =LOG('CPI base year 2015-01'!E6) -> 2.0028806
A8: 2015-M06 | B8: =LOG('CPI base year 2015-01'!B7) -> 2.0025323 | C8: =LOG('CPI base year 2015-01'!C7) -> 2.0004065 | D8: =LOG('CPI base year 2015-01'!D7) -> 2.0012189 | E8: =LOG('CPI base year 2015-01'!E7) -> 2.0052003
A9: 2015-M07 | B9: =LOG('CPI base year 2015-01'!B8) -> 2.0022472 | C9: =LOG('CPI base year 2015-01'!C8) -> 2.0012182 | D9: =LOG('CPI base year 2015-01'!D8) -> 2.0020007 | E9: =LOG('CPI base year 2015-01'!E8) -> 2.0092303
A10: 2015-M08 | B10: =LOG('CPI base year 2015-01'!B9) -> 2.001268 | C10: =LOG('CPI base year 2015-01'!C9) -> 2.0012182 | D10: =LOG('CPI base year 2015-01'!D9) -> 2.0026078 | E10: =LOG('CPI base year 2015-01'!E9) -> 2.0109103
A11: 2015-M09 | B11: =LOG('CPI base year 2015-01'!B10) -> 2.0010637 | C11: =LOG('CPI base year 2015-01'!C10) -> 2.0004065 | D11: =LOG('CPI base year 2015-01'!D10) -> 2.0014796 | E11: =LOG('CPI base year 2015-01'!E10) -> 2.0106962
A12: 2015-M10 | B12: =LOG('CPI base year 2015-01'!B11) -> 2.001921 | C12: =LOG('CPI base year 2015-01'!C11) -> 2.0008125 | D12: =LOG('CPI base year 2015-01'!D11) -> 2.0014796 | E12: =LOG('CPI base year 2015-01'!E11) -> 2.0103391
A13: 2015-M11 | B13: =LOG('CPI base year 2015-01'!B12) -> 2.0005322 | C13: =LOG('CPI base year 2015-01'!C12) -> 2.0020285 | D13: =LOG('CPI base year 2015-01'!D12) -> 2.0006557 | E13: =LOG('CPI base year 2015-01'!E12) -> 2.0112313
A14: 2015-M12 | B14: =LOG('CPI base year 2015-01'!B13) -> 1.9988515 | C14: =LOG('CPI base year 2015-01'!C13) -> 2.0028372 | D14: =LOG('CPI base year 2015-01'!D13) -> 2.001955 | E14: =LOG('CPI base year 2015-01'!E13) -> 2.0153825
... A125: 2025-M03 | B125: =LOG('CPI base year 2015-01'!B124) -> 2.0439193 | C125: =LOG('CPI base year 2015-01'!C124) -> 2.147579 | D125: =LOG('CPI base year 2015-01'!D124) -> 2.0894539 | E125: =LOG('CPI base year 2015-01'!E124) -> 2.1266214
A126: 2025-M04 | C126: =LOG('CPI base year 2015-01'!C125) -> 2.1458765 | D126: =LOG('CPI base year 2015-01'!D125) -> 2.0897899 | E126: =LOG('CPI base year 2015-01'!E125) -> 2.1316553
A127: 2025-M05 | C127: =LOG('CPI base year 2015-01'!C126) -> 2.1455352 | D127: =LOG('CPI base year 2015-01'!D126) -> 2.0893792 | E127: =LOG('CPI base year 2015-01'!E126) -> 2.1300508
A128: 2025-M06 | C128: =LOG('CPI base year 2015-01'!C127) -> 2.1458765 | D128: =LOG('CPI base year 2015-01'!D127) -> 2.0895286 | E128: =LOG('CPI base year 2015-01'!E127) -> 2.1308538
A129: 2025-M07 | C129: =LOG('CPI base year 2015-01'!C128) -> 2.147239 | D129: =LOG('CPI base year 2015-01'!D128) -> 2.090312 | E129: =LOG('CPI base year 2015-01'!E128) -> 2.1321755
A130: 2025-M08 | C130: =LOG('CPI base year 2015-01'!C129) -> 2.1499513 | D130: =LOG('CPI base year 2015-01'!D129) -> 2.090051 | E130: =LOG('CPI base year 2015-01'!E129) -> 2.1318154
A131: 2025-M09 | C131: =LOG('CPI base year 2015-01'!C130) -> 2.1499513 | D131: =LOG('CPI base year 2015-01'!D130) -> 2.09232 | E131: =LOG('CPI base year 2015-01'!E130) -> 2.132735
